Some weights of the model checkpoint at microsoft/deberta-v3-large were not used when initializing DebertaV2Model: ['mask_predictions.classifier.weight', 'lm_predictions.lm_head.dense.bias', 'mask_predictions.dense.weight', 'mask_predictions.LayerNorm.weight', 'lm_predictions.lm_head.bias', 'lm_predictions.lm_head.LayerNorm.bias', 'lm_predictions.lm_head.dense.weight', 'mask_predictions.dense.bias', 'mask_predictions.LayerNorm.bias', 'lm_predictions.lm_head.LayerNorm.weight', 'mask_predictions.classifier.bias']
- This IS expected if you are initializing DebertaV2Model from the checkpoint of a model trained on another task or with another architecture (e.g. initializing a BertForSequenceClassification model from a BertForPreTraining model).
- This IS NOT expected if you are initializing DebertaV2Model from the checkpoint of a model that you expect to be exactly identical (initializing a BertForSequenceClassification model from a BertForSequenceClassification model).
[1/5] Train & Validation
/home/qcqced/anaconda3/lib/python3.9/site-packages/transformers/optimization.py:391: FutureWarning: This implementation of AdamW is deprecated and will be removed in a future version. Use the PyTorch implementation torch.optim.AdamW instead, or set `no_deprecation_warning=True` to disable this warning
  warnings.warn(
  0%|                                                                                                               | 0/780 [00:00<?, ?it/s]
Traceback (most recent call last):                                                                                  | 0/780 [00:00<?, ?it/s]
  File "/home/qcqced/바탕화면/ML_Test/FeedBackPrize_2/train.py", line 19, in <module>
    main('fbp2_config.json', CFG)
  File "/home/qcqced/바탕화면/ML_Test/FeedBackPrize_2/train.py", line 15, in main
    getattr(train_loop, cfg.loop)(cfg)
  File "/home/qcqced/바탕화면/ML_Test/FeedBackPrize_2/trainer/train_loop.py", line 34, in train_loop
    train_loss = train_input.train_fn(
  File "/home/qcqced/바탕화면/ML_Test/FeedBackPrize_2/trainer/trainer.py", line 113, in train_fn
    loss = criterion(pred, labels)
  File "/home/qcqced/anaconda3/lib/python3.9/site-packages/torch/nn/modules/module.py", line 1501, in _call_impl
    return forward_call(*args, **kwargs)
  File "/home/qcqced/바탕화면/ML_Test/FeedBackPrize_2/model/loss.py", line 113, in forward
    return criterion(y_pred, y_true)
  File "/home/qcqced/anaconda3/lib/python3.9/site-packages/torch/nn/modules/module.py", line 1501, in _call_impl
    return forward_call(*args, **kwargs)
  File "/home/qcqced/anaconda3/lib/python3.9/site-packages/torch/nn/modules/loss.py", line 1174, in forward
    return F.cross_entropy(input, target, weight=self.weight,
  File "/home/qcqced/anaconda3/lib/python3.9/site-packages/torch/nn/functional.py", line 3029, in cross_entropy
    return torch._C._nn.cross_entropy_loss(input, target, weight, _Reduction.get_enum(reduction), ignore_index, label_smoothing)
RuntimeError: Expected target size [16, 15], got [16, 2048]