Traceback (most recent call last):
  File "/home/qcqced/anaconda3/lib/python3.9/site-packages/huggingface_hub/utils/_errors.py", line 259, in hf_raise_for_status
    response.raise_for_status()
  File "/home/qcqced/anaconda3/lib/python3.9/site-packages/requests/models.py", line 1021, in raise_for_status
    raise HTTPError(http_error_msg, response=self)
requests.exceptions.HTTPError: 401 Client Error: Unauthorized for url: https://huggingface.co/longformer/resolve/main/config.json
The above exception was the direct cause of the following exception:
Traceback (most recent call last):
  File "/home/qcqced/anaconda3/lib/python3.9/site-packages/transformers/utils/hub.py", line 409, in cached_file
    resolved_file = hf_hub_download(
  File "/home/qcqced/anaconda3/lib/python3.9/site-packages/huggingface_hub/utils/_validators.py", line 120, in _inner_fn
    return fn(*args, **kwargs)
  File "/home/qcqced/anaconda3/lib/python3.9/site-packages/huggingface_hub/file_download.py", line 1195, in hf_hub_download
    metadata = get_hf_file_metadata(
  File "/home/qcqced/anaconda3/lib/python3.9/site-packages/huggingface_hub/utils/_validators.py", line 120, in _inner_fn
    return fn(*args, **kwargs)
  File "/home/qcqced/anaconda3/lib/python3.9/site-packages/huggingface_hub/file_download.py", line 1541, in get_hf_file_metadata
    hf_raise_for_status(r)
  File "/home/qcqced/anaconda3/lib/python3.9/site-packages/huggingface_hub/utils/_errors.py", line 291, in hf_raise_for_status
    raise RepositoryNotFoundError(message, response) from e
huggingface_hub.utils._errors.RepositoryNotFoundError: 401 Client Error. (Request ID: Root=1-648761bb-61f634a96903a7cf6540453d)
Repository Not Found for url: https://huggingface.co/longformer/resolve/main/config.json.
Please make sure you specified the correct `repo_id` and `repo_type`.
If you are trying to access a private or gated repo, make sure you are authenticated.
Invalid username or password.
During handling of the above exception, another exception occurred:
Traceback (most recent call last):
  File "/home/qcqced/바탕화면/ML_Test/FeedBackPrize_2/train.py", line 21, in <module>
    main('fbp2_LongFormer_config.json', CFG)
  File "/home/qcqced/바탕화면/ML_Test/FeedBackPrize_2/train.py", line 16, in main
    getattr(train_loop, cfg.loop)(cfg)
  File "/home/qcqced/바탕화면/ML_Test/FeedBackPrize_2/trainer/train_loop.py", line 31, in train_loop
    model, criterion, val_metrics, optimizer, lr_scheduler = train_input.model_setting(len(train))
  File "/home/qcqced/바탕화면/ML_Test/FeedBackPrize_2/trainer/trainer.py", line 75, in model_setting
    model = getattr(model_arch, self.cfg.model_arch)(self.cfg)
  File "/home/qcqced/바탕화면/ML_Test/FeedBackPrize_2/model/model.py", line 23, in __init__
    self.auto_cfg = AutoConfig.from_pretrained(
  File "/home/qcqced/anaconda3/lib/python3.9/site-packages/transformers/models/auto/configuration_auto.py", line 916, in from_pretrained
    config_dict, unused_kwargs = PretrainedConfig.get_config_dict(pretrained_model_name_or_path, **kwargs)
  File "/home/qcqced/anaconda3/lib/python3.9/site-packages/transformers/configuration_utils.py", line 573, in get_config_dict
    config_dict, kwargs = cls._get_config_dict(pretrained_model_name_or_path, **kwargs)
  File "/home/qcqced/anaconda3/lib/python3.9/site-packages/transformers/configuration_utils.py", line 628, in _get_config_dict
    resolved_config_file = cached_file(
  File "/home/qcqced/anaconda3/lib/python3.9/site-packages/transformers/utils/hub.py", line 424, in cached_file
    raise EnvironmentError(
OSError: longformer is not a local folder and is not a valid model identifier listed on 'https://huggingface.co/models'
If this is a private repository, make sure to pass a token having permission to this repo with `use_auth_token` or log in with `huggingface-cli login` and pass `use_auth_token=True`.