Traceback (most recent call last):
  File "/home/qcqced/anaconda3/lib/python3.9/site-packages/pandas/core/indexes/base.py", line 3629, in get_loc
    return self._engine.get_loc(casted_key)
  File "pandas/_libs/index.pyx", line 136, in pandas._libs.index.IndexEngine.get_loc
  File "pandas/_libs/index.pyx", line 163, in pandas._libs.index.IndexEngine.get_loc
  File "pandas/_libs/hashtable_class_helper.pxi", line 5198, in pandas._libs.hashtable.PyObjectHashTable.get_item
  File "pandas/_libs/hashtable_class_helper.pxi", line 5206, in pandas._libs.hashtable.PyObjectHashTable.get_item
KeyError: True
The above exception was the direct cause of the following exception:
Traceback (most recent call last):
  File "/home/qcqced/바탕화면/ML_Test/FeedBackPrize_2/train.py", line 19, in <module>
    main('fbp2_config.json', CFG)
  File "/home/qcqced/바탕화면/ML_Test/FeedBackPrize_2/train.py", line 15, in main
    getattr(train_loop, cfg.loop)(cfg)
  File "/home/qcqced/바탕화면/ML_Test/FeedBackPrize_2/trainer/train_loop.py", line 29, in train_loop
    loader_train, loader_valid, train = train_input.make_batch(fold)
  File "/home/qcqced/바탕화면/ML_Test/FeedBackPrize_2/trainer/trainer.py", line 38, in make_batch
    train = self.df[self.df['fold'] != fold].reset_index(drop=True)
  File "/home/qcqced/anaconda3/lib/python3.9/site-packages/pandas/core/series.py", line 958, in __getitem__
    return self._get_value(key)
  File "/home/qcqced/anaconda3/lib/python3.9/site-packages/pandas/core/series.py", line 1069, in _get_value
    loc = self.index.get_loc(label)
  File "/home/qcqced/anaconda3/lib/python3.9/site-packages/pandas/core/indexes/base.py", line 3631, in get_loc
    raise KeyError(key) from err
KeyError: True